ERROR:ex:Error!
Traceback (most recent call last):
  File ".\logging2.py", line 7, in <module>
    raise RuntimeError
RuntimeError
